Workbook

Sheet AFTECOOLLER
A1: DESCRIÇÃO | B1: LOCAÇÃO ANTERIOR | C1: ATUAL | D1: PRÓXIMA SAÍDA | E1: VALIDADE | F1: ESLINGA | G1: VALIDADE | H1: DIMENSÕES | I1: PESO
A2: CME-AFTE.001 | B2: SBM | C2: BASE | D2: MV26 | E2: 46428 | F2: BC-2303862 | G2: 46428 | H2: 2000 x 2440 x 2500 | I2: 3000
A3: CME-AFTE.002 | B3: MODEC | C3: BASE | D3: MV26 | E3: 46539 | F3: BC-2526478 | G3: 46539 | H3: 2000 x 2440 x 2500 | I3: 3000
A4: CME-AFTE.003 | B4: SBM | C4: BASE | D4: SAQUAREMA | E4: 46463 | F4: BC-2526474 | G4: 46463 | H4: 2000 x 2440 x 2500 | I4: 3000
A5: CME-AFTE.004 | B5: SBM | C5: BASE | D5: ALM. TAMANDARE | E5: 46539 | F5: BC-2526480 | G5: 46539 | H5: 2000 x 2440 x 2500 | I5: 3000
A6: CME-AFTE.005 | B6: BW ENERGY | C6: BASE | D6: BASE | E6: 46539 | F6: BC-26038 | G6: 46539 | H6: 2000 x 2440 x 2500 | I6: 3000
A7: CME-AFTE.006 | B7: BW ENERGY | C7: BASE | D7: BASE | E7: 46428 | H7: 2000 x 2440 x 2500 | I7: 3000 | J7: PEGAR NO PALLET NO FUNDO DO GALPÃO
A8: CME-AFTE.007 | B8: SBM | C8: BASE | D8: MV26 | E8: 46539 | F8: BC-2303860 | G8: 46539 | H8: 2000 x 2440 x 2500 | I8: 3000
A9: CME-AFTE.008 | B9: SBM | C9: BASE | D9: BASE | E9: 46463 | F9: BC-2303859 | G9: 46463 | H9: 2000 x 2440 x 2500 | I9: 3000
A10: CME-AFTE.009 | B10: SBM | C10: SBM | D10: ANCHIETA | E10: 46437 | F10: 3749 | G10: 46437 | H10: 3000 x 2000 x 2400 | I10: 4500 | J10: CERTIFICAR A BORDO - HGM
A11: CME-AFTE-PQ-002 | B11: MODEC | C11: BASE | D11: BASE | E11: 46325 | F11: 1697 | G11: 46325 | H11: 2650 x 1600 x 1600 | I11: 1100

Sheet BOOSTER
A1: DESCRIÇÃO | B1: LOCAÇÃO ANTERIOR | C1: ATUAL | D1: PRÓXIMA SAÍDA | E1: VALIDADE | F1: ESLINGA | G1: VALIDADE | H1: DIMENSÕES | I1: PESO
A2: CME-BDN.001 | B2: SCHLUMBERGER | C2: BASE | D2: BASE | E2: 46476 | F2: BC-2526485 | G2: 46476 | H2: 6058 x 2438 x 2590 | I2: 14000
A3: CME-BDN.002 | B3: SBM | C3: BASE | D3: BASE | E3: 46476 | F3: BC-2526484 | G3: 46476 | H3: 6058 x 2438 x 2590 | I3: 14000
A4: CME-BDN.003 | B4: SBM | C4: CME | D4: GUIANA | E4: 46511 | F4: BC-2526483 | G4: 46511 | H4: 6058 x 2438 x 2590 | I4: 14000
A5: CME-BDN.004 (67190009) | B5: HALLIBURTON | C5: BASE | D5: MV26 | E5: 46476 | F5: BC-2412787 | G5: 46476 | H5: 6058 x 2438 x 2590 | I5: 14000
A6: CME-BDN.005 (67190010) | B6: SBM | C6: BASE | D6: SAQUAREMA | E6: 46476 | F6: JF141001637 | G6: 46476 | H6: 6058 x 2438 x 2590 | I6: 14000
A7: CME-BDN.006 | B7: MODEC | C7: BASE | D7: BASE | E7: 46476 | F7: 240100967 | G7: 46476 | H7: 6058 x 2438 x 2590 | I7: 14000
A8: CME-BDN.007 | B8: BW ENERGY | C8: BASE | D8: ALM. TAMANDARE | E8: 46477 | F8: 240400360 | G8: 46477 | H8: 6058 x 2438 x 2590 | I8: 14000

Sheet BOMBA LIMPEZA QUIMICA
A1: DESCRIÇÃO | B1: LOCAÇÃO ANTERIOR | C1: ATUAL | D1: PRÓXIMA SAÍDA | E1: VALIDADE | F1: ESLINGA | G1: VALIDADE | H1: DIMENSÕES | I1: PESO
A2: CME-BLQE.003 | B2: SBM | C2: BASE | D2: BASE | E2: 45982 | F2: S/ESLINGA | G2: S/ESLINGA | H2: 2500 x 2000 x 2500 | I2: 2000
A3: CME-BLQE.004 | B3: EQUINOR | C3: BASE | D3: BASE | E3: 45850 | F3: S/ESLINGA | G3: S/ESLINGA | H3: 2500 x 1900 x 2000 | I3: 4500
A4: CME-BLQE.005 | B4: SBM | C4: BASE | D4: BASE | E4: 45850 | F4: S/ESLINGA | G4: S/ESLINGA | H4: 2500 x 2000 x 2500 | I4: 4500
A5: CME-BLQE.006 | B5: SBM | C5: BASE | D5: SAQUAREMA | E5: 46539 | F5: BC-26039 | G5: 46428 | H5: 3000 x 2000 x 1850 | I5: 4500 | J5: PEGAR DO AFTER.006
A6: CME-BLQE.007 | B6: SBM | C6: BASE | D6: BASE | E6: 46428 | F6: L7-69873 | G6: 46428 | H6: 3000 x 2000 x 2370 | I6: 4500
A7: CME.BLQE.008 | B7: - | C7: BASE | D7: BASE | E7: 44365 | F7: S/ESLINGA | H7: 3000 x 2000 x 2370 | I7: 4500
A8: CME.BLQE.009 | B8: - | C8: ????? | D8: ????? | E8: 45203 | F8: S/ESLINGA | H8: 2500 x 1800 x 2150 | I8: 2200
A9: CME-BLQE.010 | B9: SBM | C9: SBM | D9: MARICA | E9: 46428 | F9: 009 | G9: 46428 | H9: 3000 x 2000 x 1850 | I9: 4500
A10: CME-BLQE.011 | B10: SBM | C10: BASE | D10: PARATY | E10: 46428 | F10: BC-2303861 | G10: 46428 | H10: 3000 x 2000 x 2370 | I10: 4500
A11: CME-BLQE.012 | B11: SBM | C11: MODEC | D11: MV24 | E11: 46228 | F11: 1608 | G11: 46228 | H11: 3000 x 2000 x 1850 | I11: 4500
A12: CME-BLQE.013 | B12: TRIDENT | C12: BASE | D12: ILHA BELA | E12: 46428 | F12: BC-2303864 | G12: 46428 | H12: 3000 x 2000 x 2370 | I12: 4500

Sheet CALDEIRA
A1: DESCRIÇÃO | B1: LOCAÇÃO ANTERIOR | C1: ATUAL | D1: PRÓXIMA SAÍDA | E1: VALIDADE | F1: ESLINGA | G1: VALIDADE | H1: DIMENSÕES | I1: PESO
A2: CME-SKD-CALD.001 | B2: MODEC | C2: BASE | D2: MV26 | E2: 46428 | F2: 220406114 | G2: 46428 | H2: 4600 x 2430 x 2900 | I2: 10000
A3: CME-SKD-CALD.002 | B3: SBM | C3: BASE | D3: SAQUAREMA | E3: 46428 | F3: 11103-111704 | G3: 46428 | H3: 6050 x 2430 x 2590 | I3: 14000
A4: CME-SKD-CALD.003 | B4: MODEC | C4: BASE | D4: BASE | E4: 46428 | F4: 1110311 | G4: 46428 | H4: 5500 x 2400 x 2500 | I4: 13000

Sheet CONTAINER
A1: IDENTIFICAÇÃO | B1: INFO ADICIONAL | C1: LOCAÇÃO ANTERIOR | D1: ATUAL | E1: PRÓXIMA SAÍDA | F1: VALIDADE | G1: ESLINGA | H1: VALIDADE | I1: OBS
A2: CME-DNV-024 | C2: MODEC | D2: BASE | E2: BASE | F2: 46510 | G2: VERIF. | H2: 46280 | I2: ESLINGA REPROVADA
A3: CME-DNV-025 | C3: SBM | D3: BASE | E3: BASE | F3: 46510 | G3: VERIF. | H3: 46280 | I3: ESLINGA REPROVADA
A4: CME-DNV-026 | C4: SBM | D4: BASE | E4: SAQUAREMA | F4: 46510 | G4: BC-2303109 | H4: 46540
A5: CME-DNV-027 | C5: MODEC | D5: BASE | E5: BASE | F5: 46429 | G5: 230800288 | H5: 46429
A6: CME-DNV-028 | C6: TRIDENT | D6: BASE | E6: MV26 | F6: 46540 | G6: 230800289 | H6: 46540
A7: CME-DNV-029 | B7: PRATELEIRA*** | C7: MODEC | D7: BASE | E7: PARATY | F7: 46540 | G7: 250300264 | H7: 46540 | I7: 230800290 - REPROVADA
A8: CME-DNV-030 | C8: MODEC | D8: BASE | E8: MV26 | F8: 46510 | G8: 230800291 | H8: 46510
A9: CME-DNV-031 | C9: SBM | D9: BASE | E9: MV26 | F9: 46510 | G9: 230800292 | H9: 46510
A10: CME-DNV-032 | B10: PRATELEIRA | C10: SBM | D10: MODEC | E10: MV24 | F10: 46429 | G10: 230800293 | H10: 46429
A11: CME-DNV-033 | C11: SBM | D11: BASE | E11: MV26 | F11: 46510 | G11: 230800285 | H11: 46510
A12: CME-DNV-034 | C12: SBM | D12: BASE | E12: PARATY | F12: 46477 | G12: 230800295 | H12: 46477
A13: CME-DNV-035 | C13: SBM | D13: BASE | E13: BASE | F13: 46510 | G13: 230800296 | H13: 46510 | I13: CHEIO DE ESFERA DO MOLSIEVE
A14: CME-DNV-036 | C14: TRIDENT | D14: BASE | E14: BASE | F14: 46540 | G14: 230800297 | H14: 46540
A15: CME-DNV-037 | C15: SBM | D15: BASE | E15: ALM. TAMANDARE | F15: 46510 | G15: 230800298 | H15: 46510
A16: CME-DNV-038 | C16: SBM | D16: BASE | E16: BASE | F16: 46510 | G16: 230800299 | H16: 46280 | I16: ESLINGA REPROVADA
A17: CME-DNV-039 | C17: SBM | D17: BASE | E17: BASE | F17: 46510 | G17: 230800300 | H17: 46280 | I17: ESLINGA REPROVADA
A18: DNVU105149-7 | C18: SBM | D18: BASE | E18: BASE | F18: 46429 | G18: IA0166/22-2 | H18: 46429
A19: DNVU105159-0 | B19: ARMARIO | C19: MODEC | D19: BASE | E19: SAQUAREMA | F19: 46540 | G19: 250300262 | H19: 46540 | I19: L7-59880 - REPROVADA
A20: DNVU105160-3 | B20: ARMARIO | C20: MISC | D20: BASE | E20: MV26 | F20: 46429 | G20: BC-59714 | H20: 46429
A21: DNVU105164-5 | C21: SBM | D21: SBM | E21: ANCHIETA | F21: 46429 | G21: BC-26036 | H21: 46429 | I21: CONTAINER SUBSTITUINDO DNVU105220-9
A22: DNVU105166-6 | C22: MODEC | D22: BASE | E22: BASE | F22: 46477 | G22: 250300260 | H22: 46477
A23: DNVU105170-6 | B23: PRATELEIRA | C23: SBM | D23: BASE | E23: PARATY | F23: 46429 | G23: L7-65902/3 | H23: 46429
A24: DNVU105174-8 | C24: SBM | D24: BASE | E24: SAQUAREMA | F24: 46429 | G24: IA0166/22-1 | H24: 46429
A25: DNVU105176-9 | B25: MOLSIEVE DEDICADO | C25: MODEC | D25: BASE | E25: MV26 | F25: 46477 | G25: BC-59713 | H25: 46477
A26: DNVU105181-4 | B26: PRATELEIRA | C26: SBM | D26: BASE | E26: SAQUAREMA | F26: 46429 | G26: L7-61032 | H26: 46429
A27: DNVU105203-0 | C27: SBM | D27: SBM | E27: MARICA | F27: 46429 | G27: L7-59879 | H27: 46429
A28: DNVU105206-6 | C28: SBM | D28: BASE | E28: SAQUAREMA | F28: 46429 | G28: L7-60199 | H28: 46429
A29: DNVU105207-1 | C29: MODEC | D29: BASE | E29: BASE | F29: 46429 | G29: L7-61035 | H29: 46429 | I29: REFORMA NO TETO - URGENTE
A30: DNVU105220-9 | C30: SBM | D30: BASE | E30: BASE | F30: S/ESLINGA | G30: S/ESLINGA | H30: S/ESLINGA | I30: CERTIFICADO A BORDO - HGM - FAZER REFORMA / PINTURA
A31: DNVU105221-4 | B31: PRATELEIRA | C31: SBM | D31: SBM | E31: MARICA | F31: 46477 | G31: L7-66641 | H31: 46477
A32: DNVU105229-8 | C32: BW ENERGY | D32: BASE | E32: GUIANA | F32: 46477 | G32: L7-65902/1 | H32: 46477 | I32: OBS: LIXAR SOLDAS DOS OLHAIS PARA INSPEÇÃO
A33: DNVU105230-1 | B33: CAMPI BLOQUEADO | C33: SBM | D33: BASE | E33: BASE | F33: S/ESLINGA | G33: S/ESLINGA | H33: S/ESLINGA
A34: DNVU105231-7 | C34: MODEC | D34: BASE | E34: BEERENBERG | F34: 46429 | G34: L7-59878 | H34: 46429
A35: DNVU105235-9 | B35: PRATELEIRA | C35: SBM | D35: BASE | E35: BASE | F35: 46540 | G35: S/ ESLINGA | H35: 46540 | I35: MATERIAL DO CAMPI
A36: DNVU105238-5 | C36: MODEC | D36: BASE | E36: BASE | F36: 46429 | G36: L7-60197 | H36: 46429
A37: DNVU105250-7 | B37: ARMARIO | C37: SBM | D37: CME | E37: GUIANA | F37: 46477 | G37: L7-59681 | H37: 46477
A38: DNVU105266-2 | B38: REFORMA E PINTURA | C38: MODEC | D38: BASE | E38: BASE | F38: 46280 | G38: BC-2303108 | H38: 46280 | I38: TETO FURADO
A39: DNVU105277-0 | C39: SBM | D39: BASE | E39: SAQUAREMA | F39: 46510 | G39: L7-60198 | H39: 46540
A40: DNVU105285-2 | B40: PRATELEIRA | C40: SBM | D40: MODEC | E40: MV24 | F40: 46429 | G40: 284 | H40: 46429
...

Sheet CONTAINER HIDROJATO
A1: IDENTIFICAÇÃO | B1: INFO ADICIONAL | C1: LOCAÇÃO ANTERIOR | D1: ATUAL | E1: PRÓXIMA SAÍDA | F1: VALIDADE | G1: ESLINGA | H1: VALIDADE
A2: JCFU100009-7 | B2: L75/100 -- 4 CILINDROS | C2: SBM | D2: BASE | E2: BASE | F2: 46540 | G2: L7-70005 | H2: 46540
A3: JCFU100016-3 | C3: SBM | D3: SBM | E3: MARICA | F3: 46477 | G3: 169012 | H3: 46477
A4: JCFU100043-5 | C4: SBM | D4: MODEC | E4: MV31 | F4: 46429 | G4: L7-61033 | H4: 46429
A5: JCFU100054-3 | B5: L120/3 -- 4 CILINDROS | C5: SBM | D5: BASE | E5: SAQUAREMA | F5: 46477 | G5: BC-26035 | H5: 46477
A6: JCFU100057-0 | B6: L75/100 -- 4 CILINDROS | C6: SBM | D6: BASE | E6: PARATY | F6: 46540 | G6: 230800284 | H6: 46540 | I6: SOS12A/00225 - REPROVADA
A7: MLTU040145-0 (20PES) | C7: MODEC | D7: BASE | E7: BASE | F7: 46429 | G7: 200204929 | H7: 46429

Sheet MEMBRANA
A1: DESCRIÇÃO | B1: LOCAÇÃO ANTERIOR | C1: ATUAL | D1: PRÓXIMA SAÍDA | E1: VALIDADE | F1: ESLINGA | G1: VALIDADE
A2: DNV131001 - UGN.001 | B2: CONTINENTAL | C2: CONTINENTAL | D2: CME USA | E2: 45449 | F2: S/ESLINGA | G2: S/ESLINGA | H2: SAÍDA 18/12/23 - CONTINENTAL USA
A3: DNV181001 - UGN.002 | B3: MODEC | C3: BASE | D3: BASE | E3: 46477 | F3: 250300265 | G3: 46477
A4: PCUU6950013 - UGN.003 | B4: SBM | C4: BASE | D4: BASE | E4: 46477 | F4: BC-59715 | G4: 46477
A5: JCFU100024-5 - UGN.004 | B5: CONTINENTAL | C5: CONTINENTAL | D5: CME USA | E5: 45448 | F5: S/ESLINGA | G5: S/ESLINGA | H5: SAÍDA 18/12/23 - CONTINENTAL USA
A6: DNVU105162-4 - UGN.005 | B6: BW ENERGY | C6: BASE | D6: MV26 | E6: 46540 | F6: L7-66644 | G6: 46540
A7: DNVU105234-3 - UGN.006 | B7: SBM | C7: BASE | D7: SAQUAREMA | E7: 46478 | F7: L7-69950 | G7: 46478
A8: DNVU105208-7 - UGN.007 | B8: MODEC | C8: BASE | D8: MV26 | E8: 46429 | F8: BC-59712 | G8: 46429
A9: CME-DNV-021 - UGN.008 | B9: MODEC | C9: BASE | D9: ALM. TAMANDARE | E9: 46477 | F9: 230800282 | G9: 46477
A10: CME-DNV-020 - UGN.009 | B10: SBM | C10: BASE | D10: BASE | E10: 46477 | F10: 230800281 | G10: 46477
A11: CME-DNV-022 - (UGN.010) | B11: IMPORTADO | C11: CONTINENTAL | D11: CME USA | E11: 46070 | F11: 230800283 | G11: 46247 | H11: SAÍDA 07/08/25 - CONTINENTAL USA
A12: CME-DNV-023 - (UGN.011) | B12: IMPORTADO | C12: CONTINENTAL | D12: CME USA | E12: 46070 | F12: S/ESLINGA | G12: 46247 | H12: SAÍDA 07/08/25 - CONTINENTAL USA
A13: OGSU202506-7 (UGN12) | B13: IMPORTADO | C13: CONTINENTAL | D13: CME USA | E13: 46323 | F13: S/ESLINGA | G13: 46323 | H13: SAÍDA 08/12/25 - CONTINENTAL USA
A14: OGSU202511-2 (UGN13) | B14: IMPORTADO | C14: CONTINENTAL | D14: CME USA | E14: 46323 | F14: S/ESLINGA | G14: 46323 | H14: SAÍDA 08/12/25 - CONTINENTAL USA
A15: OGSU202510-7 - (UGN-14?) | B15: IMPORTADO | C15: CONTINENTAL | D15: CME USA | E15: 46323 | F15: S/ESLINGA | G15: 46323 | H15: SAÍDA 14/04/26 - CONTINENTAL USA
A16: OGSU202508-8 (UGN-15? | B16: IMPORTADO | C16: CONTINENTAL | D16: CME USA | F16: S/ESLINGA | H16: SAÍDA 14/04/26 - CONTINENTAL USA

Sheet QUAD GAS
A1: IDENTIFICAÇÃO | B1: GASES | C1: LOCAÇÃO ANTERIOR | D1: ATUAL | E1: PRÓXIMA SAÍDA | F1: PROCESSO | G1: QUANTIDADE | H1: VALIDADE | I1: ESLINGA | J1: VALIDADE | K1: OBS
A2: CME-DNV-QUAD.001 | B2: HELIO | C2: SBM | D2: BASE | E2: SAQUAREMA | F2: 6863 | G2: LACRADO | H2: 46477 | I2: 240108557 | J2: 46477
A3: CME-DNV-QUAD.002 | B3: HELIO | C3: SBM | D3: BASE | E3: MV26 | F3: 6804 | G3: 185BAR | H3: 46477 | I3: 240108558 | J3: 46477
A4: CME-DNV-QUAD.003 | B4: NITROGENIO | C4: TRANSOCEAN | D4: BASE | E4: BASE | F4: *** | G4: 160BAR | H4: 46540 | I4: 240108559 | J4: 46540
A5: CME-DNV-QUAD.004 | B5: NITROGENIO | C5: EQUINOR | D5: MISC | E5: MDDC | F5: 6425 | G5: A BORDO | H5: 46154 | I5: 240108560 | J5: 46154
A6: CME-DNV-QUAD.005 | B6: HELIO | C6: SBM | D6: BASE | E6: MV26 | F6: 6804 | G6: LACRADO | H6: 46477 | I6: 240108561 | J6: 46477
A7: CME-DNV-QUAD.006 | B7: HELIO | C7: WHITE MARTINS | D7: BASE | E7: MV26 | F7: 6804 | G7: LACRADO | H7: 46477 | I7: 240108562 | J7: 46477
A8: CME-DNV-QUAD.007 | B8: HELIO | C8: MISC | D8: BASE | E8: MV26 | F8: 6804 | G8: LACRADO | H8: 46477 | I8: 240108563 | J8: 46477
A9: CME-DNV-QUAD.008 | B9: HELIO | C9: MODEC | D9: BASE | E9: BASE | F9: *** | G9: 165BAR | H9: 46477 | I9: 240108564 | J9: 46477 | K9: EM USO NA BASE
A10: CME-DNV-QUAD.009 | B10: NITROGENIO | C10: SBM | D10: BASE | E10: BASE | F10: *** | G10: 165BAR | H10: 46477 | I10: 240108565 | J10: 46477
A11: CME-DNV-QUAD.010 | B11: NITROGENIO | C11: SBM | D11: BASE | E11: BASE | F11: *** | G11: 203BAR | H11: 46479 | I11: 240108566 | J11: 46479
A12: CME-DNV-QUAD.011 | B12: HELIO | C12: SBM | D12: BASE | E12: SAQUAREMA | F12: 6863 | G12: 165BAR | H12: 46477 | I12: 240108567 | J12: 46477
A13: CME-DNV-QUAD.012 | B13: HELIO | C13: SBM | D13: BASE | E13: SAQUAREMA | F13: 6863 | G13: 175BAR | H13: 46477 | I13: 240108568 | J13: 46477
A14: CME-DNV-QUAD.013 | B14: HELIO | C14: SBM | D14: BASE | E14: SAQUAREMA | F14: 6863 | G14: 180BAR | H14: 46477 | I14: 240108569 | J14: 46477
A15: CME-DNV-QUAD.014 | B15: HELIO | C15: MODEC | D15: BASE | E15: MV26 | F15: 6874 | G15: LACRADO | H15: 46478 | I15: 240108570 | J15: 46478
A16: CME-DNV-QUAD.015 | B16: HELIO | C16: WHITE MARTINS | D16: BASE | E16: BASE | F16: *** | G16: LACRADO | H16: 46477 | I16: 240108571 | J16: 46477
A17: CME-DNV-QUAD.016 | B17: HELIO | C17: WHITE MARTINS | D17: BASE | E17: ALM. TAMANDARE | F17: 6891 | G17: 170BAR | H17: 46477 | I17: 240108572 | J17: 46477
A18: CME-DNV-QUAD.017 | B18: NITROGENIO | C18: TRANSOCEAN | D18: BASE | E18: MDDC | F18: 6425 | G18: 165BAR | H18: 46477 | I18: 240108573 | J18: 46477
A19: CME-DNV-QUAD.018 | B19: NITROGENIO | C19: SBM | D19: BASE | E19: BASE | F19: *** | G19: 175BAR | H19: 46477 | I19: 240108574 | J19: 46477
A20: CME-DNV-QUAD.019 | B20: NITROGENIO | C20: GUEREN GASES | D20: BASE | E20: BASE | F20: *** | G20: 180BAR | H20: 46540 | I20: 240108575 | J20: 46540
A21: CME-DNV-QUAD.020 | B21: HELIO | C21: WHITE MARTINS | D21: BASE | E21: BASE | F21: *** | G21: LACRADO | H21: 46478 | I21: 240108576 | J21: 46478
A22: R16-13-23287 | B22: AIR DIVE | C22: WHITE MARTINS | D22: BASE | E22: MV26 | F22: 6874 | G22: 200BAR | H22: 46429 | I22: 2049 | J22: 46429
A23: CME-DNV-QUAD.021 | B23: HELIO | C23: MODEC | D23: BASE | E23: BASE | F23: *** | G23: LACRADO | H23: 46540 | I23: 250500500 | J23: 46540
A24: CME-DNV-QUAD.022 | B24: HELIO | C24: MODEC | D24: BASE | E24: BASE | F24: *** | G24: 175BAR | H24: 46540 | I24: 250500501 | J24: 46540
A25: CME-DNV-QUAD.023 | B25: HELIO | C25: MODEC | D25: BASE | E25: BASE | F25: *** | G25: LACRADO | H25: 46540 | I25: 250500502 | J25: 46540
A26: CME-DNV-QUAD.024 | B26: HELIO | C26: MODEC | D26: BASE | E26: BASE | F26: *** | G26: LACRADO | H26: 46540 | I26: 250500503 | J26: 46540
A27: CME-DNV-QUAD.025 | B27: HELIO | C27: SBM | D27: BASE | E27: BASE | F27: *** | G27: 165BAR | H27: 46540 | I27: 250500504 | J27: 46540
A28: CME-DNV-QUAD.026 | B28: HELIO | C28: MODEC | D28: BASE | E28: BASE | F28: *** | G28: LACRADO | H28: 46540 | I28: 250500505 | J28: 46540
A29: CME-DNV-QUAD.027 | B29: HELIO | C29: SBM | D29: BASE | E29: BASE | F29: *** | G29: LACRADO | H29: 46540 | I29: 250500506 | J29: 46540
A30: CME-DNV-QUAD.028 | B30: NITROGENIO | C30: SBM | D30: BASE | E30: MDDC | F30: 6425 | G30: 170BAR | H30: 46477 | I30: 250500507 | J30: 46477
A31: CME-DNV-QUAD.029 | B31: NITROGENIO | C31: SBM | D31: BASE | E31: BASE | F31: *** | G31: 185BAR | H31: 46477 | I31: 250500508 | J31: 46477 | K31: SWIRE PRECISA GERAR CERTIFICADO, ESTÁ DUPLICADO COM O QUAD 24
A32: CME-DNV-QUAD.030 | B32: NITROGENIO | C32: SBM | D32: BASE | E32: BASE | F32: *** | G32: 175BAR | H32: 46477 | I32: 250500509 | J32: 46477
A33: CME-DNV-QUAD.031 | B33: NITROGENIO | C33: WHITE MARTINS | D33: SBM | E33: PARATY | F33: 6758 | G33: A BORDO | H33: 46196 | I33: 250500510 | J33: 46172 | K33: CERTIFICAR SWIRE
A34: CME-DNV-QUAD.032 | B34: NITROGENIO | C34: WHITE MARTINS | D34: BASE | E34: BASE | F34: *** | G34: LACRADO | H34: 46540 | I34: 250500511 | J34: 46540
A35: CME-DNV-QUAD.033 | B35: NITROGENIO | C35: SBM | D35: BASE | E35: BASE | F35: *** | G35: 190BAR | H35: 46477 | I35: 250500512 | J35: 46477
A36: CME-DNV-QUAD.034 | B36: NITROGENIO | C36: TRIDENT | D36: BASE | E36: BASE | F36: *** | G36: LACRADO | H36: 46540 | I36: 250500513 | J36: 46540
A37: CME-DNV-QUAD.035 | B37: NITROGENIO | C37: WHITE MARTINS | D37: BASE | E37: BASE | F37: *** | G37: LACRADO | H37: 46540 | I37: 250500514 | J37: 46540
A38: CME-DNV-QUAD.036 | B38: NITROGENIO | C38: WHITE MARTINS | D38: BASE | E38: BASE | F38: *** | G38: LACRADO | H38: 46540 | I38: 250500515 | J38: 46540
A39: CME-DNV-QUAD.037 | B39: NITROGENIO | C39: WHITE MARTINS | D39: SBM | E39: PARATY | F39: 6758 | G39: A BORDO | H39: 46196 | I39: 250500516 | J39: 46172 | K39: CERTIFICAR SWIRE
A40: CME-DNV-QUAD.038 | B40: NITROGENIO | C40: WHITE MARTINS | D40: BASE | E40: BASE | F40: *** | G40: LACRADO | H40: 46540 | I40: 250500517 | J40: 46540

Sheet COMPRESSORES
A1: DESCRIÇÃO | B1: LOCAÇÃO ANTERIOR | C1: ATUAL | D1: PRÓXIMA SAÍDA | E1: VALIDADE | F1: ESLINGA | G1: VALIDADE | H1: DIMENSÕES | I1: PESO
A2: CME-AIR-COMP.001 | B2: SBM | C2: BASE | D2: MV26 | E2: 46539 | F2: L7-59689 | G2: 46539 | H2: 5000 x 2440 x 2650 | I2: 10000
A3: CME-AIR-COMP.002 | B3: SBM | C3: BASE | D3: MV26 | E3: 46428 | F3: BC-2412784 | G3: 46428 | H3: 5000 x 2440 x 2650 | I3: 10000
A4: CME-AIR-COMP.003 | B4: MODEC | C4: BASE | D4: BASE | E4: 46428 | F4: BC-2412785 | G4: 46428 | H4: 5000 x 2440 x 2650 | I4: 10000
A5: CME-AIR-COMP.004 | B5: SBM | C5: BASE | D5: BASE | E5: 46428 | F5: 2529 | G5: 46428 | H5: 5000 x 2440 x 2650 | I5: 10000 | J5: VENDIDO COMP. 004 E SKID COM COMP. 008.
A6: CME-AIR-COMP.005 | B6: SBM | C6: BASE | D6: MV26 | E6: 46463 | F6: BC-2303865 | G6: 46463 | H6: 5000 x 2440 x 2650 | I6: 10000
A7: CME-AIR-COMP.006 | B7: SBM | C7: BASE | D7: BASE | E7: 46463 | F7: L7-59638 | G7: 46463 | H7: 5000 x 2440 x 2650 | I7: 10000
A8: CME-AIR-COMP.007 | B8: SBM | C8: BASE | D8: BASE | E8: 46463 | F8: 10448-2 | G8: 46463 | H8: 5000 x 2440 x 2650 | I8: 10000
A9: CME-AIR-COMP.008 | B9: SUBSEA7 | C9: BASE | D9: BASE | E9: S/ESLINGA | F9: S/ESLINGA | G9: S/ESLINGA | H9: 5000 x 2440 x 2650 | I9: 10000 | J9: COMP. SEM SKID DEVIDO A LOCAÇÃO.
A10: CME-AIR-COMP.009 | B10: SBM | C10: BASE | D10: MV26 | E10: 46539 | F10: 168487 | G10: 46539 | H10: 5000 x 2440 x 2650 | I10: 10000
A11: CME-AIR-COMP.010 | B11: SUBSEA7 | C11: BASE | D11: BASE | E11: 46428 | F11: L7-68383 | G11: 46428 | H11: 5000 x 2440 x 2650 | I11: 10000
A12: CME-AIR-COMP.011 | B12: MODEC | C12: BASE | D12: BASE | E12: 46428 | F12: BC-2412783 | G12: 46428 | H12: 5000 x 2440 x 2650 | I12: 10000 | J12: MANUTENÇÃO???
A13: CME-AIR-COMP.012 | B13: BW ENERGY | C13: BASE | D13: BASE | E13: 46228 | F13: 10448-3 | G13: 46228 | H13: 5000 x 2440 x 2650 | I13: 10000 | J13: SKID VAZIO
A14: CME-AIR-COMP.013 | B14: MODEC | C14: BASE | D14: BASE | E14: 46428 | F14: SOS12A/00855 | G14: 46428 | H14: 5000 x 2440 x 2650 | I14: 10000
A15: CME-AIR-COMP.014 | B15: SBM | C15: BASE | D15: BASE | E15: 45829 | F15: S/ESLINGA | G15: S/ESLINGA | H15: 5000 x 2440 x 2650 | I15: 10000 | J15: MANUTENÇÃO
A16: CME-AIR-COMP.015 | B16: SBM | C16: SBM | D16: ANCHIETA | E16: 46437 | F16: 708621 | G16: 46437 | H16: 5000 x 2440 x 2650 | I16: 10000 | J16: CERTIFICADO A BORDO - HGM
A17: CME-AIR-COMP.016 | B17: SBM | C17: SBM | D17: ANCHIETA | E17: 46442 | F17: BC-2302943 | G17: 46442 | H17: 5000 x 2440 x 2650 | I17: 10000 | J17: CERTIFICADO NO ARM-CAXIAS - HGM
A18: CME-AIR-COMP.017 | B18: BW ENERGY | C18: BASE | D18: MV26 | E18: 46463 | F18: BC-2304204 | G18: 46463 | H18: 5000 x 2440 x 2650 | I18: 10000 | J18: FPSO VITORIA - AGUARD. SAIDA
A19: CME-AIR-COMP.018 | B19: BW ENERGY | C19: BASE | D19: FPSO VITORIA | E19: 46463 | F19: BC-2302944 | G19: 46463 | H19: 5000 x 2440 x 2650 | I19: 10000
A20: CME-AIR-COMP.019 | B20: MODEC | C20: BASE | D20: BASE | E20: 46477 | F20: BC-2412786 | G20: 46477 | H20: 6058 x 2438 x 2896 | I20: 11000 | J20: CERTIFICADOS PELA SWIRE
A21: CME-AIR-COMP.020 | B21: MODEC | C21: BASE | D21: BASE | E21: 46477 | F21: 210303897 | G21: 46477 | H21: 6058 x 2438 x 2896 | I21: 11000 | J21: CERTIFICADOS PELA SWIRE
A22: CME-AIR-COMP.021 | B22: SBM | C22: BASE | D22: ALM. TAMANDARE | E22: 46428 | F22: 231204565 | G22: 46428 | H22: 6058 x 2438 x 2896 | I22: 11000
A23: CME-AIR-COMP.022 | B23: SBM | C23: BASE | D23: ALM. TAMANDARE | E23: 46428 | F23: 231204564 | G23: 46428 | H23: 6058 x 2438 x 2896 | I23: 11000
A24: CME-AIR-COMP.023 | B24: MODEC | C24: BASE | D24: SAQUAREMA | E24: 46348 | F24: LME-2601 | G24: 46347 | H24: 6058 x 2438 x 2896 | I24: 11000 | J24: CERTIFICADOS PELA SWIRE
A25: CME-AIR-COMP.024 | B25: MODEC | C25: BASE | D25: SAQUAREMA | E25: 46348 | F25: LME-2602 | G25: 46347 | H25: 6058 x 2438 x 2896 | I25: 11000 | J25: CERTIFICADOS PELA SWIRE
A26: CME-AIR-COMP.025 | B26: MODEC | C26: BASE | D26: BASE | E26: 46374 | F26: LME-2603 | G26: 46370 | H26: 6058 x 2438 x 2896 | I26: 11000 | J26: CERTIFICADOS PELA SWIRE - EM MANUTENÇÃO

Sheet SAAD
A1: DESCRIÇÃO | B1: LOCAÇÃO ANTERIOR | C1: ATUAL | D1: PRÓXIMA SAÍDA | E1: VALIDADE | F1: ESLINGA | G1: VALIDADE | H1: DIMENSÕES | I1: PESO
A2: CME-SAAD.001 | B2: MODEC | C2: BASE | D2: BASE | E2: 45210 | F2: S/ESLINGA | G2: S/ESLINGA | H2: 2960 x 1720 x 3260 | I2: 7000 | J2: DESCONTINUAR!
A3: CME-SAAD.002 | B3: MODEC | C3: SBM | D3: ANCHIETA | E3: 46438 | F3: L7-65902/4 | G3: 46438 | H3: 3000 x 2000 x 3140 | I3: 6000 | J3: CERTIFICADO A BORDO - HGM
A4: CME-SAAD.003 | B4: SBM | C4: BASE | D4: BASE | E4: 45470 | F4: S/ESLINGA | G4: S/ESLINGA | H4: 2670 x 2410 x 2800 | I4: 6000 | J4: EM MANUTENÇÃO
A5: CME-SAAD.004 | B5: SBM | C5: BASE | D5: BASE | E5: 45829 | F5: L7-70004 | G5: 45829 | H5: 3000 x 2410 x 2950 | I5: 6000 | J5: EM MANUTENÇÃO
A6: CME-SAAD.005 | B6: SBM | C6: BASE | D6: BASE | E6: 46539 | F6: BC-2303110 | G6: 46539 | H6: 3000 x 2000 x 3140 | I6: 6000
A7: CME-SAAD.006 | B7: SBM | C7: BASE | D7: MV26 | E7: 46539 | F7: BC-2303863 | G7: 46539 | H7: 3000 x 2000 x 3140 | I7: 6000
A8: CME-SAAD.007 | B8: MODEC | C8: BASE | D8: BASE | E8: 46539 | F8: CME 008 | G8: 46539 | H8: 3000 x 2000 x 3140 | I8: 6000

Sheet MOLSIEVE
A1: DESCRIÇÃO | B1: LOCAÇÃO ANTERIOR | C1: ATUAL | D1: PRÓXIMA SAÍDA | E1: VALIDADE | F1: ESLINGA | G1: VALIDADE | H1: DIMENSÕES | I1: PESO
A2: CME-VAC-001 | B2: MODEC | C2: BASE | D2: MV26 | E2: 46539 | F2: BC-26244 | G2: 46539 | H2: 2210 x 2100 x 2190 | I2: 1800
A3: CME-FHO-001 | B3: MODEC | C3: BASE | D3: MV26 | E3: 46539 | F3: BC-26246 | G3: 46539 | H3: 1800 x 1800 x 2190 | I3: 1200
A4: CME-CIC-001 | B4: MODEC | C4: BASE | D4: MV26 | E4: 46539 | F4: BC-26245 | G4: 46539 | H4: 1800 x 1800 x 2190 | I4: 1600
A5: CME-SFL-001 | B5: MODEC | C5: BASE | D5: MV26 | E5: 46539 | F5: 1 | G5: 46539 | H5: 1500 x 1500 x 2190 | I5: 1000
A6: CME-SIL-001 | B6: MODEC | C6: BASE | D6: MV26 | E6: 46539 | F6: CME-03-25 | G6: 46539 | H6: 1710 x 1540 x 2100 | I6: 1100
A7: CME-SIL-002 | B7: MODEC | C7: BASE | D7: MV26 | E7: 46539 | F7: CME-04-25 | G7: 46539 | H7: 1710 x 1540 x 2100 | I7: 1100

Sheet VASO DE PRESSÃO
A1: DESCRIÇÃO | B1: LOCAÇÃO ANTERIOR | C1: ATUAL | D1: PRÓXIMA SAÍDA | E1: VALIDADE | F1: ESLINGA | G1: VALIDADE | H1: DIMENSÕES | I1: PESO
A2: CME-V.D.P.100 | B2: SBM | C2: BASE | D2: MV26 | E2: 46539 | F2: BC-2526481 | G2: 46539 | H2: 2000 x 2000 x 3660 | I2: 6500
A3: CME-V.D.P.101 | B3: SBM | C3: BASE | D3: BASE | E3: 45829 | F3: 5046-1 | G3: 45829 | H3: 2000 x 2000 x 3660 | I3: 5500 | J3: MANUTENÇÃO
A4: CME-V.D.P.102 | B4: SBM | C4: SBM | D4: ANCHIETA | E4: 46438 | F4: 5148-4 | G4: 46438 | H4: 2000 x 2000 x 4500 | I4: 7200 | J4: CERTIFICADO A BORDO - HGM

Sheet TANQUE
A1: DESCRIÇÃO | B1: LOCAÇÃO ANTERIOR | C1: ATUAL | D1: PRÓXIMA SAÍDA | E1: VALIDADE | F1: ESLINGA | G1: VALIDADE | H1: DIMENSÕES | I1: PESO
A2: SCZU-87346-3 | B2: YINSON | C2: BASE | D2: BASE | E2: *** | F2: *** | G2: *** | H2: 6050 x 2430 x 2590 | I2: 6000 | J2: FIXO PARA MOLSIVE
A3: TOLU-916108-1 | B3: YINSON | C3: BASE | D3: BASE | E3: *** | F3: *** | G3: *** | H3: 6050 x 2430 x 2590 | I3: 6000 | J3: FIXO PARA MOLSIVE
A4: CME-MDT-DNV.001 | B4: SBM | C4: BASE | D4: SAQUAREMA | E4: 46477 | F4: CME-01-25 | G4: 46477 | H4: 2212 x 1852 x 1485 | I4: 2000 | J4: CERTIFICADOS PELA SWIRE
A5: CME-MDT-DNV.002 | B5: SBM | C5: BASE | D5: SAQUAREMA | E5: 46477 | F5: CME-02-25 | G5: 46477 | H5: 2212 x 1852 x 1485 | I5: 2000 | J5: CERTIFICADOS PELA SWIRE
A6: CME-MDT-DNV.003 | B6: SBM | C6: BASE | D6: SAQUAREMA | E6: 46477 | F6: BC-2527246 | G6: 46477 | H6: 2212 x 1852 x 1485 | I6: 2000 | J6: CERTIFICADOS PELA SWIRE
A7: CME-MDT-DNV.004 | B7: SBM | C7: BASE | D7: SAQUAREMA | E7: 46477 | F7: BC-2527247 | G7: 46477 | H7: 2212 x 1852 x 1485 | I7: 2000 | J7: CERTIFICADOS PELA SWIRE

Sheet DIVERSOS
A1: DESCRIÇÃO | B1: LOCAÇÃO ANTERIOR | C1: ATUAL | D1: PRÓXIMA SAÍDA | E1: VALIDADE | F1: ESLINGA | G1: VALIDADE | H1: DIMENSÕES | I1: PESO
A2: CME.CMF.001 | B2: SBM | C2: BASE | D2: BASE | E2: S/ESLINGA | F2: S/ESLINGA | G2: S/ESLINGA | H2: 1600 x 1020 x 2060 | I2: 1000
A3: CME.BF2M.001 | B3: MODEC | C3: BASE | D3: BASE | E3: S/ESLINGA | F3: S/ESLINGA | G3: S/ESLINGA
A4: CME-BF2M.002 | B4: BASE | C4: BASE | D4: BASE | E4: 45507 | F4: 001 | G4: 45507
A5: CME-BFHW.001 | B5: BASE | C5: BASE | D5: BASE | E5: S/ESLINGA | F5: S/ESLINGA | G5: S/ESLINGA
A6: CME-SKID-COMP.029 | B6: MODEC | C6: BASE | D6: MV26 | E6: 46539 | F6: 5148-3 | G6: 46539 | H6: 3000 x 2000 x 2980 | I6: 1000
A7: CME-COMP.101 | B7: BASE | C7: SUBSEA7 | D7: SUBSEA7 | E7: 46430 | F7: L7-69938 | G7: 46430 | H7: 3000 x 2000 x 2300 | I7: 2000
A8: CME-HSL.018 (EVAPORADORA) | B8: SCHLUMBERGER | C8: BASE | D8: BASE | E8: 46429 | F8: RF0391 | G8: 46429 | H8: 4572 x 2438 x 2600 | I8: 11000 | J8: CERTIFICADOS PELA SWIRE
A9: CME-NSV.001 (BERÇO) | B9: BASE | C9: BASE | D9: EQUINOR | E9: 46470 | F9: GL-84738/65 | G9: 46470 | H9: 1800 X 800 X 450 | I9: 140

Sheet GERAL
A1: DESCRIÇÃO | B1: LOCAÇÃO | C1: ATUAL | D1: VALIDADE | E1: ESLINGA | F1: VALIDADE
A2: =AFTECOOLLER!A2 -> CME-AFTE.001 | B2: =AFTECOOLLER!B2 -> SBM | C2: =AFTECOOLLER!C2 -> BASE | D2: =AFTECOOLLER!E2 -> 46428 | E2: =AFTECOOLLER!F2 -> BC-2303862 | F2: =AFTECOOLLER!G2 -> 46428
A3: =AFTECOOLLER!A3 -> CME-AFTE.002 | B3: =AFTECOOLLER!B3 -> MODEC | C3: =AFTECOOLLER!C3 -> BASE | D3: =AFTECOOLLER!E3 -> 46539 | E3: =AFTECOOLLER!F3 -> BC-2526478 | F3: =AFTECOOLLER!G3 -> 46539
A4: =AFTECOOLLER!A4 -> CME-AFTE.003 | B4: =AFTECOOLLER!B4 -> SBM | C4: =AFTECOOLLER!C4 -> BASE | D4: =AFTECOOLLER!E4 -> 46463 | E4: =AFTECOOLLER!#REF! -> #REF! | F4: =AFTECOOLLER!G4 -> 46463
A5: =AFTECOOLLER!A5 -> CME-AFTE.004 | B5: =AFTECOOLLER!B5 -> SBM | C5: =AFTECOOLLER!C5 -> BASE | D5: =AFTECOOLLER!E5 -> 46539 | E5: =AFTECOOLLER!F5 -> BC-2526480 | F5: =AFTECOOLLER!G5 -> 46539
A6: =AFTECOOLLER!A6 -> CME-AFTE.005 | B6: =AFTECOOLLER!B6 -> BW ENERGY | C6: =AFTECOOLLER!C6 -> BASE | D6: =AFTECOOLLER!E6 -> 46539 | E6: =AFTECOOLLER!F6 -> BC-26038 | F6: =AFTECOOLLER!G6 -> 46539
A7: =AFTECOOLLER!A7 -> CME-AFTE.006 | B7: =AFTECOOLLER!B7 -> BW ENERGY | C7: =AFTECOOLLER!C7 -> BASE | D7: =AFTECOOLLER!E7 -> 46428 | E7: =AFTECOOLLER!F7 -> 0 | F7: =AFTECOOLLER!G7 -> 0
A8: =AFTECOOLLER!A8 -> CME-AFTE.007 | B8: =AFTECOOLLER!B8 -> SBM | C8: =AFTECOOLLER!C8 -> BASE | D8: =AFTECOOLLER!E8 -> 46539 | E8: =AFTECOOLLER!F8 -> BC-2303860 | F8: =AFTECOOLLER!G8 -> 46539
A9: =AFTECOOLLER!A9 -> CME-AFTE.008 | B9: =AFTECOOLLER!B9 -> SBM | C9: =AFTECOOLLER!C9 -> BASE | D9: =AFTECOOLLER!E9 -> 46463 | E9: =AFTECOOLLER!F9 -> BC-2303859 | F9: =AFTECOOLLER!G9 -> 46463
A10: =AFTECOOLLER!A10 -> CME-AFTE.009 | B10: =AFTECOOLLER!B10 -> SBM | C10: =AFTECOOLLER!C10 -> SBM | D10: =AFTECOOLLER!E10 -> 46437 | E10: =AFTECOOLLER!F10 -> 3749 | F10: =AFTECOOLLER!G10 -> 46437
A11: =BOOSTER!A2 -> CME-BDN.001 | B11: =BOOSTER!B2 -> SCHLUMBERGER | C11: =BOOSTER!C2 -> BASE | D11: =BOOSTER!E2 -> 46476 | E11: =AFTECOOLLER!F11 -> 1697 | F11: =BOOSTER!G2 -> 46476
A12: =BOOSTER!A3 -> CME-BDN.002 | B12: =BOOSTER!B3 -> SBM | C12: =BOOSTER!C3 -> BASE | D12: =BOOSTER!E3 -> 46476 | E12: =BOOSTER!F3 -> BC-2526484 | F12: =BOOSTER!G3 -> 46476
A13: =BOOSTER!A4 -> CME-BDN.003 | B13: =BOOSTER!B4 -> SBM | C13: =BOOSTER!C4 -> CME | D13: =BOOSTER!E4 -> 46511 | E13: =BOOSTER!F4 -> BC-2526483 | F13: =BOOSTER!G4 -> 46511
A14: =BOOSTER!A5 -> CME-BDN.004 (67190009) | B14: =BOOSTER!B5 -> HALLIBURTON | C14: =BOOSTER!C5 -> BASE | D14: =BOOSTER!E5 -> 46476 | E14: =BOOSTER!F5 -> BC-2412787 | F14: =BOOSTER!G5 -> 46476
A15: =BOOSTER!A6 -> CME-BDN.005 (67190010) | B15: =BOOSTER!B6 -> SBM | C15: =BOOSTER!C6 -> BASE | D15: =BOOSTER!E6 -> 46476 | E15: =BOOSTER!F6 -> JF141001637 | F15: =BOOSTER!G6 -> 46476
A16: ='BOMBA LIMPEZA QUIMICA'!#REF! -> #REF! | B16: ='BOMBA LIMPEZA QUIMICA'!#REF! -> #REF! | C16: ='BOMBA LIMPEZA QUIMICA'!#REF! -> #REF! | D16: ='BOMBA LIMPEZA QUIMICA'!#REF! -> #REF! | E16: ='BOMBA LIMPEZA QUIMICA'!#REF! -> #REF! | F16: ='BOMBA LIMPEZA QUIMICA'!#REF! -> #REF!
A17: ='BOMBA LIMPEZA QUIMICA'!#REF! -> #REF! | B17: ='BOMBA LIMPEZA QUIMICA'!#REF! -> #REF! | C17: ='BOMBA LIMPEZA QUIMICA'!#REF! -> #REF! | D17: ='BOMBA LIMPEZA QUIMICA'!#REF! -> #REF! | E17: ='BOMBA LIMPEZA QUIMICA'!#REF! -> #REF! | F17: ='BOMBA LIMPEZA QUIMICA'!#REF! -> #REF!
A18: =BOOSTER!A7 -> CME-BDN.006 | B18: =BOOSTER!C7 -> BASE | C18: =BOOSTER!C7 -> BASE | D18: =BOOSTER!E7 -> 46476 | E18: =BOOSTER!F9 -> 0 | F18: =BOOSTER!G7 -> 46476
A19: =BOOSTER!A8 -> CME-BDN.007 | B19: =BOOSTER!C8 -> BASE | C19: =BOOSTER!C8 -> BASE | D19: =BOOSTER!E8 -> 46477 | E19: =BOOSTER!F10 -> 0 | F19: =BOOSTER!G8 -> 46477
A20: ='BOMBA LIMPEZA QUIMICA'!A2 -> CME-BLQE.003 | B20: ='BOMBA LIMPEZA QUIMICA'!C2 -> BASE | C20: ='BOMBA LIMPEZA QUIMICA'!D2 -> BASE | D20: ='BOMBA LIMPEZA QUIMICA'!E2 -> 45982 | E20: ='BOMBA LIMPEZA QUIMICA'!F2 -> S/ESLINGA | F20: ='BOMBA LIMPEZA QUIMICA'!G2 -> S/ESLINGA
A21: ='BOMBA LIMPEZA QUIMICA'!A3 -> CME-BLQE.004 | B21: ='BOMBA LIMPEZA QUIMICA'!C3 -> BASE | C21: ='BOMBA LIMPEZA QUIMICA'!D3 -> BASE | D21: ='BOMBA LIMPEZA QUIMICA'!E3 -> 45850 | E21: ='BOMBA LIMPEZA QUIMICA'!F3 -> S/ESLINGA | F21: ='BOMBA LIMPEZA QUIMICA'!G3 -> S/ESLINGA
A22: ='BOMBA LIMPEZA QUIMICA'!A4 -> CME-BLQE.005 | B22: ='BOMBA LIMPEZA QUIMICA'!C4 -> BASE | C22: ='BOMBA LIMPEZA QUIMICA'!D4 -> BASE | D22: ='BOMBA LIMPEZA QUIMICA'!E4 -> 45850 | E22: ='BOMBA LIMPEZA QUIMICA'!F4 -> S/ESLINGA | F22: ='BOMBA LIMPEZA QUIMICA'!G4 -> S/ESLINGA
A23: ='BOMBA LIMPEZA QUIMICA'!A5 -> CME-BLQE.006 | B23: ='BOMBA LIMPEZA QUIMICA'!C5 -> BASE | C23: ='BOMBA LIMPEZA QUIMICA'!D5 -> SAQUAREMA | D23: ='BOMBA LIMPEZA QUIMICA'!E5 -> 46539 | E23: ='BOMBA LIMPEZA QUIMICA'!F5 -> BC-26039 | F23: ='BOMBA LIMPEZA QUIMICA'!G5 -> 46428
A24: ='BOMBA LIMPEZA QUIMICA'!A6 -> CME-BLQE.007 | B24: ='BOMBA LIMPEZA QUIMICA'!C6 -> BASE | C24: ='BOMBA LIMPEZA QUIMICA'!D6 -> BASE | D24: ='BOMBA LIMPEZA QUIMICA'!E6 -> 46428 | E24: ='BOMBA LIMPEZA QUIMICA'!F6 -> L7-69873 | F24: ='BOMBA LIMPEZA QUIMICA'!G6 -> 46428
A25: ='BOMBA LIMPEZA QUIMICA'!A7 -> CME.BLQE.008 | B25: ='BOMBA LIMPEZA QUIMICA'!C7 -> BASE | C25: ='BOMBA LIMPEZA QUIMICA'!D7 -> BASE | D25: ='BOMBA LIMPEZA QUIMICA'!E7 -> 44365 | E25: ='BOMBA LIMPEZA QUIMICA'!F7 -> S/ESLINGA | F25: ='BOMBA LIMPEZA QUIMICA'!G7 -> 0
A26: ='BOMBA LIMPEZA QUIMICA'!A8 -> CME.BLQE.009 | B26: ='BOMBA LIMPEZA QUIMICA'!C8 -> ????? | C26: ='BOMBA LIMPEZA QUIMICA'!D8 -> ????? | D26: ='BOMBA LIMPEZA QUIMICA'!E8 -> 45203 | E26: ='BOMBA LIMPEZA QUIMICA'!F8 -> S/ESLINGA | F26: ='BOMBA LIMPEZA QUIMICA'!G8 -> 0
A27: ='BOMBA LIMPEZA QUIMICA'!A9 -> CME-BLQE.010 | B27: ='BOMBA LIMPEZA QUIMICA'!C9 -> SBM | C27: ='BOMBA LIMPEZA QUIMICA'!D9 -> MARICA | D27: ='BOMBA LIMPEZA QUIMICA'!E9 -> 46428 | E27: ='BOMBA LIMPEZA QUIMICA'!F9 -> 009 | F27: ='BOMBA LIMPEZA QUIMICA'!G9 -> 46428
A28: ='BOMBA LIMPEZA QUIMICA'!A10 -> CME-BLQE.011 | B28: ='BOMBA LIMPEZA QUIMICA'!C10 -> BASE | C28: ='BOMBA LIMPEZA QUIMICA'!D10 -> PARATY | D28: ='BOMBA LIMPEZA QUIMICA'!E10 -> 46428 | E28: ='BOMBA LIMPEZA QUIMICA'!F10 -> BC-2303861 | F28: ='BOMBA LIMPEZA QUIMICA'!G10 -> 46428
A29: =CALDEIRA!A2 -> CME-SKD-CALD.001 | B29: =CALDEIRA!#REF! -> #REF! | C29: =CALDEIRA!#REF! -> #REF! | D29: =CALDEIRA!E2 -> 46428 | E29: =CALDEIRA!F2 -> 220406114 | F29: =CALDEIRA!G2 -> 46428
A30: =CALDEIRA!A3 -> CME-SKD-CALD.002 | B30: =CALDEIRA!C3 -> BASE | C30: =CALDEIRA!D3 -> SAQUAREMA | D30: =CALDEIRA!E3 -> 46428 | E30: =CALDEIRA!F3 -> 11103-111704 | F30: =CALDEIRA!G3 -> 46428
A31: =CALDEIRA!A4 -> CME-SKD-CALD.003 | B31: =CALDEIRA!C4 -> BASE | C31: =CALDEIRA!D4 -> BASE | D31: =CALDEIRA!E4 -> 46428 | E31: =CALDEIRA!F4 -> 1110311 | F31: =CALDEIRA!G4 -> 46428
A32: =CONTAINER!A2 -> CME-DNV-024 | B32: =CONTAINER!D2 -> BASE | C32: =CONTAINER!E2 -> BASE | D32: =CONTAINER!F2 -> 46510 | E32: =CONTAINER!G2 -> VERIF. | F32: =CONTAINER!H2 -> 46280
A33: =CONTAINER!A3 -> CME-DNV-025 | B33: =CONTAINER!D3 -> BASE | C33: =CONTAINER!E3 -> BASE | D33: =CONTAINER!F3 -> 46510 | E33: =CONTAINER!G3 -> VERIF. | F33: =CONTAINER!H3 -> 46280
A34: =CONTAINER!A4 -> CME-DNV-026 | B34: =CONTAINER!D4 -> BASE | C34: =CONTAINER!E4 -> SAQUAREMA | D34: =CONTAINER!F4 -> 46510 | E34: =CONTAINER!G4 -> BC-2303109 | F34: =CONTAINER!H4 -> 46540
A35: =CONTAINER!A5 -> CME-DNV-027 | B35: =CONTAINER!D5 -> BASE | C35: =CONTAINER!E5 -> BASE | D35: =CONTAINER!F5 -> 46429 | E35: =CONTAINER!G5 -> 230800288 | F35: =CONTAINER!H5 -> 46429
A36: =CONTAINER!A6 -> CME-DNV-028 | B36: =CONTAINER!D6 -> BASE | C36: =CONTAINER!E6 -> MV26 | D36: =CONTAINER!F6 -> 46540 | E36: =CONTAINER!G6 -> 230800289 | F36: =CONTAINER!H6 -> 46540
A37: =CONTAINER!A7 -> CME-DNV-029 | B37: =CONTAINER!D7 -> BASE | C37: =CONTAINER!E7 -> PARATY | D37: =CONTAINER!F7 -> 46540 | E37: =CONTAINER!G7 -> 250300264 | F37: =CONTAINER!H7 -> 46540
A38: =CONTAINER!A8 -> CME-DNV-030 | B38: =CONTAINER!D8 -> BASE | C38: =CONTAINER!E8 -> MV26 | D38: =CONTAINER!F8 -> 46510 | E38: =CONTAINER!G8 -> 230800291 | F38: =CONTAINER!H8 -> 46510
A39: =CONTAINER!A9 -> CME-DNV-031 | B39: =CONTAINER!D9 -> BASE | C39: =CONTAINER!E9 -> MV26 | D39: =CONTAINER!F9 -> 46510 | E39: =CONTAINER!G9 -> 230800292 | F39: =CONTAINER!H9 -> 46510
A40: =CONTAINER!A10 -> CME-DNV-032 | B40: =CONTAINER!D10 -> MODEC | C40: =CONTAINER!E10 -> MV24 | D40: =CONTAINER!F10 -> 46429 | E40: =CONTAINER!G10 -> 230800293 | F40: =CONTAINER!H10 -> 46429
...
